Workbook
Name CAPEX_Inicial_Total: CAPEX!$B$14
Name Costo_Mina_Unitario: 'OPEX Detail'!$B$9
Name Costo_Planta_Unitario: 'OPEX Detail'!$B$16
Name Factor_Anualidad: Valuation!#REF!
Name Factor_Conversion_TnLb: Assumptions!$B$13
Name GA_Fijo: OPEX!$B$14
Name Ley_Cobre: Assumptions!$B$7
Name Ley_Concentrado: Assumptions!$B$14
Name LOM: Valuation!$B$11
Name Mano_Obra_Fija: OPEX!$B$13
Name OPEX_Total_Anual: OPEX!$B$17
Name Payability: Assumptions!$B$9
Name Precio_Cobre: Assumptions!$B$12
Name RC_Unitario: Assumptions!$B$16
Name Recuperacion_Metalurgica: Assumptions!$B$8
Name Reservas_Totales: Assumptions!$B$79
Name Tasa_Impuesto: Assumptions!$B$80
Name Tasa_Provision_Cierre: Assumptions!$B$85
Name TC_Unitario: Assumptions!$B$15
Name TIR_Base: Valuation!$B$14
Name Toneladas_Procesadas: Assumptions!$B$6
Name WACC: Assumptions!$B$83

Sheet Cover
A1: Proyecto Cordillera Cu
A2: Modelo Económico-Financiero — Evaluación de Proyecto Minero
A4: Caso ficticio con fines educativos. Ningún dato corresponde a un yacimiento real.
A6: Etapa del proyecto | B6: Prefactibilidad (PFS)
A7: Etapa del modelo | B7: 1 — Módulo de Producción (en construcción)
A8: Analista | B8: Agus — Analista Financiero Junior / Project Evaluation Analyst
A9: Moneda | B9: USD
A10: Sistema de unidades | B10: Métrico
A11: Commodity | B11: Cobre (Cu)
A12: Producto de venta | B12: Concentrado de cobre (no cátodos)
A13: Región | B13: Cuyo, Argentina (ficticio)
A14: Versión | B14: v0.1 — Solo hoja Assumptions y Production
A17: Estructura del modelo (hojas)
A18: 1. Cover
A19: 2. Assumptions
A20: 3. Production
A21: 4. Revenue
A22: 5. OPEX
A23: 6. CAPEX
A24: 7. Taxes
A25: 8. Cash Flow
A26: 9. Valuation
A27: 10. Sensitivities
A28: 11. Scenarios
... A30: 13. OPEX Detail (hoja de soporte — desagregación de costos, Etapa 3)
A33: Tutorial (chileno) | B33: https://www.youtube.com/watch?v=lTvYc3-kPAw

Sheet Assumptions
A1: ASSUMPTIONS — Supuestos e inputs del modelo
A2: Única hoja donde se permite tipear valores directamente. Ninguna otra hoja debe contener un número hardcodeado: todo se trae por referencia desde acá.
A4: Variable | B4: Valor | C4: Unidad | D4: Tipo | E4: Fuente / Nota
A5: PRODUCCIÓN (Etapa 1)
A6: Toneladas procesadas por año (Ore processed) | B6: 10000000 | C6: t/año | D6: Supuesto | E6: Capacidad nominal de planta (PFS) — throughput de diseño
A7: Ley de cobre promedio (Head grade) | B7: 0.0055 | C7: % Cu | D7: Estimación | E7: Ley promedio LOM, modelo geológico preliminar
A8: Recuperación metalúrgica (Recovery) | B8: 0.88 | C8: % | D8: Supuesto | E8: Ensayos metalúrgicos preliminares — proceso de flotación
A9: Payability | B9: 0.965 | C9: % | D9: Supuesto | E9: Condición típica de contrato de venta de concentrado (offtake), aún no negociado
A11: INGRESOS (Etapa 2)
A12: Precio del cobre (escenario base) | B12: 4.2 | C12: USD/lb | D12: Supuesto | E12: Precio de largo plazo asumido por Planeamiento para el caso base — ficticio, no es cotización real de mercado
A13: Factor de conversión t -> lb | B13: 2204.62 | C13: lb/t | D13: Dato (constante física) | E13: 1 tonelada métrica = 2.204,62 libras
A14: Ley del concentrado (Concentrate grade) | B14: 0.3 | C14: % Cu | D14: Supuesto | E14: Ley típica de concentrado de cobre por flotación (rango real usual: 26%-32% Cu) — valor ficticio para el caso
A15: Treatment Charge (TC) | B15: 80 | C15: USD/dmt | D15: Supuesto | E15: Cargo de fundición por tonelada seca de concentrado (dmt)
A16: Refining Charge (RC) | B16: 0.08 | C16: USD/lb | D16: Supuesto | E16: Cargo de refinación por libra de metal pagable — benchmark ilustrativo, no cotización real
A18: OPEX (Etapa 3)
A19: Costo Mina — Perforación y voladura (Drilling & blasting) | B19: 0.55 | C19: USD/t procesada | D19: Supuesto | E19: Costo de perforar y volar la roca por tonelada de mineral procesado
A20: Costo Mina — Carguío (Loading) | B20: 0.45 | C20: USD/t procesada | D20: Supuesto | E20: Costo de pala/excavadora por tonelada cargada
A21: Costo Mina — Acarreo (Hauling) | B21: 1.7 | C21: USD/t procesada | D21: Supuesto | E21: Costo de camiones por tonelada acarreada — en la realidad crece con la profundidad del pit; aquí se simplifica como plano
A22: Costo Mina — Servicios mina (Mine services) | B22: 0.5 | C22: USD/t procesada | D22: Supuesto | E22: Supervisión, geotecnia, dewatering y otros servicios de mina
A23: Costo Planta — Energía (Power) | B23: 2.6 | C23: USD/t procesada | D23: Supuesto | E23: Consumo eléctrico de trituración y molienda — normalmente el mayor componente del costo planta
A24: Costo Planta — Reactivos (Reagents) | B24: 0.95 | C24: USD/t procesada | D24: Supuesto | E24: Colectores, espumantes y cal para el circuito de flotación
A25: Costo Planta — Medios de molienda (Grinding media) | B25: 0.7 | C25: USD/t procesada | D25: Supuesto | E25: Bolas de acero consumidas en el molino
A26: Costo Planta — Mantenimiento (variable, desgaste) | B26: 0.45 | C26: USD/t procesada | D26: Supuesto | E26: Componente de desgaste (revestimientos, repuestos) que escala con el tonelaje procesado
A27: Costo Planta — Mano de obra (fijo) | B27: 11000000 | C27: USD/año | D27: Supuesto | E27: Dotación de operadores, metalurgistas y supervisión — costo FIJO, no depende del tonelaje (reclasificado desde el costo variable original; ver nota de la Etapa 3)
A28: G&A (Administración y gestión) | B28: 45000000 | C28: USD/año | D28: Supuesto | E28: Estructura administrativa, seguridad, gestión ambiental — costo FIJO, no depende del tonelaje
A30: CAPEX (Etapa 4)
A31: CAPEX Mina | B31: =SUM(B38:B40) -> 74000000 | C31: USD | D31: Supuesto | E31: Desarrollo de accesos, pre-stripping (remoción inicial de estéril) y equipos mina
A32: CAPEX Planta | B32: =SUM(B41:B45) -> 66000003 | C32: USD | D32: Supuesto | E32: Planta de trituración, molienda y flotación — partida más grande, típico en minería
A33: Infraestructura | B33: =SUM(B46:B49) -> 145000000 | C33: USD | D33: Supuesto | E33: Caminos, línea eléctrica, suministro de agua, campamento
A34: Ingeniería (EPCM) | B34: =SUM(B50:B52) -> 100000000 | C34: USD | D34: Supuesto | E34: Ingeniería, procura y gestión de construcción (Engineering, Procurement, Construction Management)
A35: Contingencia | B35: 0.12 | C35: % del subtotal | D35: Supuesto | E35: Reserva por incertidumbre — nivel de precisión típico de PFS (±20-25%)
A37: CAPEX DETAIL — Componentes (Etapa 4)
A38: CAPEX Mina > Flota de equipos mina — Camiones fuera de ruta (6 x USD 6,0M) | B38: 36000000 | C38: USD | D38: Supuesto | E38: 6 camiones fuera de ruta (~190 t de capacidad), USD 6,0M c/u. Es CAPEX: activo físico, vida útil típica 8-10 años.
A39: CAPEX Mina > Flota de equipos mina — Palas/excavadoras (2 x USD 12,0M) | B39: 24000000 | C39: USD | D39: Supuesto | E39: 2 palas hidráulicas/excavadoras, USD 12,0M c/u. Es CAPEX: equipo de vida útil plurianual.
A40: CAPEX Mina > Flota de equipos mina — Perforadoras (4 x USD 3,5M) | B40: 14000000 | C40: USD | D40: Supuesto | E40: 4 equipos de perforación, USD 3,5M c/u. Es CAPEX: equipo de vida útil plurianual.
A41: CAPEX Mina > Flota de equipos mina — Equipos auxiliares (motoniveladoras, cisternas, cargadores) | B41: 21000000 | C41: USD | D41: Supuesto | E41: Flota de apoyo mina. Es CAPEX: activos físicos que se usan durante varios años.
A42: CAPEX Mina > Pre-stripping (remoción inicial de estéril) — Volumen de estéril a remover (pre-producción) | B42: 20000000 | C42: t | D42: Supuesto | E42: Volumen de estéril a mover antes del inicio de producción, según plan de minado.
A43: CAPEX Mina > Pre-stripping (remoción inicial de estéril) — Costo unitario de remoción de estéril | B43: 3 | C43: USD/t | D43: Supuesto | E43: Perforación, voladura, carguío y acarreo del estéril de pre-stripping. Es CAPEX: da acceso a todo el mineral que se extraerá en años futuros — beneficio plurianual (distinto del stripping de producción corriente, que es OPEX bajo IFRIC 20).
A44: CAPEX Mina > Obras civiles y accesos mina — Caminos internos de mina | B44: 15000000 | C44: USD | D44: Supuesto | E44: Caminos de acarreo internos entre el pit y la planta/botaderos. Es CAPEX: infraestructura permanente.
A45: CAPEX Mina > Obras civiles y accesos mina — Plataformas y drenaje | B45: 10000000 | C45: USD | D45: Supuesto | E45: Plataformas de trabajo y sistema de drenaje del área mina. Es CAPEX: obra civil de uso plurianual.
...

Sheet Production
A1: PRODUCTION — Módulo de producción (Etapa 1)
A2: Objetivo: calcular el metal pagable anual a partir de toneladas procesadas, ley, recuperación metalúrgica y payability.
A4: Concepto | B4: Valor | C4: Unidad | D4: Comentario / ayuda | F4: PSJ | G4: Veladero
A5: Toneladas procesadas | B5: =+Toneladas_Procesadas -> 10000000 | C5: t/año | F5: =42000*365 -> 15330000 | G5: =69000*365 -> 25185000
A6: Ley de cobre (head grade) | B6: =Ley_Cobre -> 0.0055 | C6: % | F6: =+F7/F5 -> 0.0048923679 | G6: =+G7/G5 -> 0.0069
A7: Metal contenido (100% Cu) | B7: =+B5*B6 -> 55000 | C7: t Cu | D7: Tu fórmula: Toneladas procesadas × Ley de cobre | F7: 75000 | G7: 173776.5
A8: Recuperación metalúrgica | B8: =Recuperacion_Metalurgica -> 0.88 | C8: % | D8: Chancado - Trituracion - Flotacion - Relave
A9: Metal recuperado (100% Cu) | B9: =+B7*B8 -> 48400 | C9: t Cu | D9: Tu fórmula: Metal contenido × Recuperación metalúrgica
A10: Payability | B10: =Payability -> 0.965 | C10: % | D10: Cordillera Cu, en este caso, no vende cátodos de cobre refinado: vende concentrado de cobre a una fundición (smelter) mediante un contrato de venta llamado off-take agreement. Ese contrato establece que la fundición no te paga por el 100% del cobre que hay en el concentrado que le entregás, sino por un porcentaje pactado —en este caso 96,5%—. ¿Por qué? Porque en el proceso de fundición y refinación también hay pérdidas metalúrgicas (del lado del smelter, no del lado de la mina), y porque es práctica comercial estándar del negocio de concentrados que el comprador se quede con una pequeña porción como "deducción" contractual | E10: Vos no vendés cobre refinado, vendés concentrado. Entonces el comprador arma una fórmula de precio que dice, en esencia: "te voy a pagar como si tu concentrado fuera cobre refinado, pero te descuento lo que a mí me costaría llegar hasta ahí".
A11: Metal pagable (100% Cu) | B11: =+B9*B10 -> 46706 | C11: t Cu | D11: Tu fórmula: Metal recuperado × Payability
A12: Control: ley pagable equivalente | B12: =+B11/B5 -> 0.0046706 | C12: % | D12: Chequeo: Metal pagable / Toneladas procesadas. Debe ser sensiblemente menor a la ley de cabeza.
A14: Depreciación (unidades de producción)
A16: Tn por año | B16: =+B5 -> 10000000
A17: Reservas totales (probadas y probables) | B17: =+Reservas_Totales -> 150000000
A18: % de tn extraidas del total | B18: =+B16/B17 -> 0.066666667
A19: CAPEX Total | B19: =+CAPEX_Inicial_Total -> -739200000
A20: Depreciation | B20: =+B18*B19 -> -49280000

Sheet Revenue
A1: REVENUE — Módulo de ingresos (Etapa 2)
A2: Objetivo: partir del metal pagable (Production) y llegar al Net Smelter Return (NSR), es decir, lo que la compañía realmente cobra después de Treatment Charge y Refining Charge.
A4: Concepto | B4: Valor | C4: Unidad | D4: Comentario / lógica
A5: PRODUCCIÓN VENDIBLE
A6: =+Production!A11 -> Metal pagable (100% Cu) | B6: =Production!$B$11 -> 46706 | C6: t Cu | D6: Referencia directa a Production — producción vendible del año.
A7: =+A6 -> Metal pagable (100% Cu) | B7: =B6*Factor_Conversion_TnLb -> 1.0296898e+08 | C7: lb Cu | D7: Conversión de toneladas a libras, porque el precio del cobre cotiza en USD/lb.
A8: Precio del cobre | B8: =Precio_Cobre -> 4.2 | C8: USD/lb
A9: Ingreso Bruto Anual | B9: =B7*B8 -> 4.3246972e+08 | C9: USD | D9: Ingreso Bruto = Metal pagable (lb) x Precio del cobre. Todavía sin descontar TC/RC.
A11: DEDUCCIONES DE FUNDICIÓN / REFINACIÓN
A12: =+Production!A9 -> Metal recuperado (100% Cu) | B12: =Production!$B$9 -> 48400 | C12: t Cu | D12: Referencia a Production — copper contenido en el concentrado entregado (antes de payability).
A13: Ley del concentrado | B13: =Ley_Concentrado -> 0.3 | C13: % Cu
A14: Toneladas de concentrado (Cu + Adicionales) | B14: =B12/B13 -> 161333.33 | C14: dmt | D14: Toneladas de concentrado" es el peso total de ese producto que sale de la planta — cobre puro más todo lo demás que viene mezclado con él (esas "impurezas" son principalmente otros minerales, sobre todo compuestos de azufre y hierro, que quedan pegados al cobre durante el proceso de flotación y no se pueden separar del todo en la mina)
A15: Treatment Charge (TC), unitario | B15: =TC_Unitario -> 80 | C15: USD/dmt
A16: Treatment Charge total | B16: =-B14*B15 -> -12906667 | C16: USD | D16: Toneladas de concentrado x TC unitario. TC es el costo de fundición que se aplica sobre todo lo que le llevás a la fundición (porque el TC nace de procesar todo lo que le diste, no de cuánto de eso te van a reconocer después)
A17: Refining Charge (RC), unitario | B17: =RC_Unitario -> 0.08 | C17: USD/lb
A18: Refining Charge total | B18: =-B7*B17 -> -8237518.5 | C18: USD | D18: Metal pagable (lb) x RC unitario. El RC se aplica sobre el metal PAGABLE, no sobre el recuperado. Si el TC se aplica sobre las toneladas de concentrado puras, y luego la empresa debe refinar lo obtenido de la fundicion, quiere decir que cuando refine hay parte del mineral que se sigue perdiendo, entonces el comprador si pagase sobre las toneladas fundidas, ganaria mas porque estaria cobrando por algo que luego termina usando por ej en un 96% cuando hace la refinacion. Entonces por eso el proceso de refinacion se hace sobre el monto de metal pagable para que el comprador no cobre un costo sobre algo que se termina perdiendo en el proceso
A19: RESULTADO
A20: Net Smelter Return (NSR) | B20: =B9+B16+B18 -> 4.1132554e+08 | C20: USD | D20: Ingreso Bruto - TC total - RC total. Esto es lo que la compañía realmente cobra por su producción anual.
A21: Control: NSR / Ingreso Bruto | B21: =B20/B9 -> 0.95110829 | C21: % | D21: Chequeo de orden de magnitud: en ventas de concentrado suele rondar 85%-95%. Muy por fuera de ese rango sugiere un error de unidades.

Sheet OPEX
A1: OPEX — Módulo de costos operativos (Etapa 3)
A2: Objetivo: calcular el OPEX Total Anual y los indicadores de costo unitario (costo por tonelada y Cash Cost por libra de cobre pagable).
A4: Concepto | B4: Valor | C4: Unidad | D4: Comentario / lógica
A5: COSTOS VARIABLES
A6: Toneladas procesadas | B6: =Toneladas_Procesadas -> 10000000 | C6: t/año | D6: Referencia directa a Assumptions — mismo tonelaje usado en Production.
A7: Costo mina, unitario | B7: ='OPEX Detail'!$B$9 -> 3.2 | C7: USD/t
A8: Costo mina, total | B8: =-B6*B7 -> -32000000 | C8: USD | D8: Toneladas procesadas x Costo mina unitario.
A9: Costo planta, unitario | B9: ='OPEX Detail'!$B$16 -> 4.7 | C9: USD/t | D9: Ya no incluye mano de obra — ver Costos Fijos.
A10: Costo planta, total | B10: =-B6*B9 -> -47000000 | C10: USD | D10: Toneladas procesadas x Costo planta unitario.
A12: COSTOS FIJOS
A13: Mano de obra de planta (fijo) | B13: =-Assumptions!$B$27 -> -11000000 | C13: USD/año | D13: Reclasificado desde costo variable: la dotación de planta no escala con el tonelaje.
A14: G&A | B14: =-Assumptions!$B$28 -> -45000000 | C14: USD/año | D14: Costo fijo anual — no se multiplica por tonelaje.
A16: RESULTADO
A17: OPEX Total Anual | B17: =B8+B10+B13+B14 -> -135000000 | C17: USD | D17: Costo mina total + Costo planta total + Mano de obra fija + G&A.
A18: Cash Cost por tonelada procesada | B18: =-OPEX_Total_Anual/B6 -> 13.5 | C18: USD/t | D18: -OPEX Total / Toneladas procesadas (positivo, es un benchmark, no una línea de flujo).
A19: Metal pagable (t) | B19: =Production!$B$11 -> 46706 | C19: t Cu | D19: Referencia a Production — base para el Cash Cost por libra.
A20: Metal pagable (lb) | B20: =B19*Factor_Conversion_TnLb -> 1.0296898e+08 | C20: lb Cu | D20: Conversión a libras, misma lógica que en Revenue.
A21: Cash Cost por libra pagable (C1) | B21: =-OPEX_Total_Anual/B20 -> 1.3110744 | C21: USD/lb | D21: -OPEX Total / Metal pagable (lb). Indicador C1 Cash Cost, positivo por convención de la industria.
A22: Cash Cost | B22: =B21/Precio_Cobre -> 0.31216058 | C22: % | D22: Chequeo: el Cash Cost no debería superar el precio de venta.

Sheet OPEX Detail
A1: OPEX DETAIL — Desagregación de Costo Mina y Costo Planta
A3: Concepto | B3: Valor | C3: Unidad | D3: Comentario / lógica
A4: COSTO MINA — COMPONENTES (USD/t procesada)
A5: Perforación y voladura | B5: =Assumptions!$B$19 -> 0.55 | C5: USD/t | D5: Es OPEX: explosivos y horas de equipo que se consumen en el momento de la voladura del período; no crea un activo que perdure.
A6: Carguío | B6: =Assumptions!$B$20 -> 0.45 | C6: USD/t | D6: Es OPEX: combustible, desgaste y mano de obra del equipo de carguío, consumidos en el período — la máquina en sí ya está capitalizada en CAPEX (Flota de equipos).
A7: Acarreo | B7: =Assumptions!$B$21 -> 1.7 | C7: USD/t | D7: Es OPEX: combustible, neumáticos y mantenimiento rutinario de los camiones — se consume mes a mes; el camión en sí es CAPEX.
A8: Servicios mina | B8: =Assumptions!$B$22 -> 0.5 | C8: USD/t | D8: Es OPEX: supervisión, geotecnia y dewatering son servicios corrientes del período, no generan un activo.
A9: Subtotal Costo Mina | B9: =SUM(B5:B8) -> 3.2 | C9: USD/t | D9: Suma de los 4 componentes. Es el valor que alimenta el Costo mina unitario en la hoja OPEX.
A11: COSTO PLANTA — COMPONENTES (USD/t procesada)
A12: Energía | B12: =Assumptions!$B$23 -> 2.6 | C12: USD/t | D12: Es OPEX: la electricidad consumida se agota en el momento de uso, no queda ningún activo.
A13: Reactivos | B13: =Assumptions!$B$24 -> 0.95 | C13: USD/t | D13: Es OPEX: los reactivos químicos se consumen en el proceso de flotación de cada tonelada procesada.
A14: Medios de molienda | B14: =Assumptions!$B$25 -> 0.7 | C14: USD/t | D14: Es OPEX: las bolas de acero se desgastan y consumen con cada tonelada molida — es un consumible, no un activo de varios años.
A15: Mantenimiento (variable, desgaste) | B15: =Assumptions!$B$26 -> 0.45 | C15: USD/t | D15: Es OPEX: reposición de piezas de desgaste — mantiene el activo en su condición normal sin extender su vida útil (a diferencia de un overhaul mayor, que sí se capitalizaría).
A16: Subtotal Costo Planta | B16: =SUM(B12:B15) -> 4.7 | C16: USD/t | D16: Suma de los 4 componentes. Es el valor que alimenta el Costo planta unitario en la hoja OPEX.

Sheet CAPEX
A1: CAPEX — Inversión de capital inicial (Etapa 4)
A2: Objetivo: calcular el CAPEX Inicial Total necesario para construir Cordillera Cu, antes de que comience a generar los ingresos y costos ya modelados.
A4: Concepto | B4: Valor | C4: Unidad | D4: Comentario / lógica
A5: INVERSIÓN INICIAL
A6: CAPEX Mina | B6: =-'CAPEX Detail'!$B$18 -> -180000000 | C6: USD | D6: Ya no viene directo de Assumptions: se trae del subtotal armado en CAPEX Detail.
A7: CAPEX Planta | B7: =-'CAPEX Detail'!$B$40 -> -340000000 | C7: USD
A8: Infraestructura | B8: =-'CAPEX Detail'!$B$59 -> -90000000 | C8: USD
A9: Ingeniería (EPCM) | B9: =-'CAPEX Detail'!$B$72 -> -50000000 | C9: USD
A10: Subtotal | B10: =SUM(B6:B9) -> -660000000 | C10: USD | D10: Suma de las cuatro partidas de inversión.
A11: Contingencia, % | B11: =Assumptions!$B$35 -> 0.12 | C11: %
A12: Contingencia, USD | B12: =B10*B11 -> -79200000 | C12: USD | D12: Subtotal x Contingencia %. Queda negativo automáticamente porque el Subtotal ya es negativo.
A13: RESULTADO
A14: CAPEX Inicial Total | B14: =B10+B12 -> -739200000 | C14: USD | D14: Subtotal + Contingencia. Es la salida de caja del año 0, antes de que arranque la operación.
A15: Control: Intensidad de capital | B15: =-CAPEX_Inicial_Total/Toneladas_Procesadas -> 73.92 | C15: USD/t capacidad | D15: -CAPEX Inicial / Toneladas procesadas por año. Mide cuánto capital se invirtió por cada tonelada de capacidad anual de planta — se usa para comparar proyectos entre sí.

Sheet CAPEX Detail
A1: CAPEX DETAIL — Desagregación de la inversión inicial
A2: Objetivo: descomponer cada partida de CAPEX hasta sus elementos de origen (equipos, volúmenes, tarifas unitarias), y documentar por qué cada uno se clasifica como CAPEX.
A4: Concepto | B4: Valor | C4: Unidad | D4: Comentario / por qué es CAPEX
A5: CAPEX MINA — COMPONENTES
A6: Camiones fuera de ruta (6 x USD 6,0M) | B6: =Assumptions!$B$38 -> 36000000 | C6: USD | D6: 6 camiones fuera de ruta (~190 t de capacidad), USD 6,0M c/u. Es CAPEX: activo físico, vida útil típica 8-10 años. | E6: En veladero son 52 camiones
A7: Palas/excavadoras (2 x USD 12,0M) | B7: =Assumptions!$B$39 -> 24000000 | C7: USD | D7: 2 palas hidráulicas/excavadoras, USD 12,0M c/u. Es CAPEX: equipo de vida útil plurianual.
A8: Perforadoras (4 x USD 3,5M) | B8: =Assumptions!$B$40 -> 14000000 | C8: USD | D8: 4 equipos de perforación, USD 3,5M c/u. Es CAPEX: equipo de vida útil plurianual.
A9: Equipos auxiliares (motoniveladoras, cisternas, cargadores) | B9: =Assumptions!$B$41 -> 21000000 | C9: USD | D9: Flota de apoyo mina. Es CAPEX: activos físicos que se usan durante varios años.
A10: Subtotal Flota de equipos mina | B10: =B6+B7+B8+B9 -> 95000000 | C10: USD | D10: Alimenta el subtotal de CAPEX Mina.
A11: Volumen de estéril a remover (pre-stripping | B11: =Assumptions!$B$42 -> 20000000 | C11: t | D11: Volumen de estéril a mover antes del inicio de producción, según plan de minado. El pre-stripping (remoción del estéril que cubre el yacimiento, hecha ANTES de que empiece la producción) es un costo que necesitás pagar una sola vez, por adelantado, para poder acceder al mineral. En ese momento todavía no estás vendiendo cobre — no hay ingresos contra los cuales "cargarle" ese gasto de un año en particular. Y el beneficio de haber sacado ese estéril no se agota en un período: te da acceso al mineral que vas a extraer durante los 15 años de vida de mina. Esa es exactamente la definición de un activo en contabilidad: una erogación que genera beneficios económicos futuros a lo largo de varios períodos, no el consumo de algo en el período corriente. Por eso se capitaliza (CAPEX, en el Año 0) en vez de tratarse como un gasto operativo de un año específico.
A12: Costo unitario de remoción de estéril | B12: =Assumptions!$B$43 -> 3 | C12: USD/t | D12: Perforación, voladura, carguío y acarreo del estéril de pre-stripping. Es CAPEX: da acceso a todo el mineral que se extraerá en años futuros — beneficio plurianual (distinto del stripping de producción corriente, que es OPEX bajo IFRIC 20).
A13: Subproducto: Volumen de estéril a remover (pre-stripping x Costo unitario de remoción de estéril | B13: =B11*B12 -> 60000000 | C13: USD
A14: Subtotal Pre-stripping (remoción inicial de estéril) | B14: =B13 -> 60000000 | C14: USD | D14: Alimenta el subtotal de CAPEX Mina.
A15: Caminos internos de mina | B15: =Assumptions!$B$44 -> 15000000 | C15: USD | D15: Caminos de acarreo internos entre el pit y la planta/botaderos. Es CAPEX: infraestructura permanente.
A16: Plataformas y drenaje | B16: =Assumptions!$B$45 -> 10000000 | C16: USD | D16: Plataformas de trabajo y sistema de drenaje del área mina. Es CAPEX: obra civil de uso plurianual.
A17: Subtotal Obras civiles y accesos mina | B17: =B15+B16 -> 25000000 | C17: USD | D17: Alimenta el subtotal de CAPEX Mina.
A18: Subtotal CAPEX Mina | B18: =B10+B14+B17 -> 180000000 | C18: USD | D18: Alimenta la línea 'CAPEX Mina' de la hoja CAPEX.
A20: CAPEX PLANTA — COMPONENTES
A21: Chancadora primaria | B21: =Assumptions!$B$46 -> 25000000 | C21: USD | D21: Es CAPEX: equipo de proceso, vida útil 15-20+ años.
A22: Chancadora secundaria/terciaria | B22: =Assumptions!$B$47 -> 15000000 | C22: USD | D22: Es CAPEX: equipo de proceso de vida útil plurianual.
A23: Correas transportadoras y estructuras | B23: =Assumptions!$B$48 -> 15000000 | C23: USD | D23: Es CAPEX: instalación fija de la planta.
A24: Subtotal Circuito de trituración | B24: =B21+B22+B23 -> 55000000 | C24: USD | D24: Alimenta el subtotal de CAPEX Planta.
A25: Molino SAG | B25: =Assumptions!$B$49 -> 90000000 | C25: USD | D25: Es CAPEX: la partida individual más cara del proyecto — equipo de proceso de vida útil de décadas.
A26: Molino de bolas | B26: =Assumptions!$B$50 -> 45000000 | C26: USD | D26: Es CAPEX: equipo de proceso de vida útil plurianual.
A27: Equipos auxiliares de molienda (clasificadores, bombas) | B27: =Assumptions!$B$51 -> 15000000 | C27: USD | D27: Es CAPEX: equipos fijos del circuito de molienda.
A28: Subtotal Circuito de molienda | B28: =B25+B26+B27 -> 150000000 | C28: USD | D28: Alimenta el subtotal de CAPEX Planta.
A29: Celdas de flotación | B29: =Assumptions!$B$52 -> 40000000 | C29: USD | D29: Es CAPEX: equipo de proceso de vida útil plurianual.
A30: Espesadores | B30: =Assumptions!$B$53 -> 20000000 | C30: USD | D30: Es CAPEX: equipo fijo de la planta.
A31: Sistema de reactivos (dosificación) | B31: =Assumptions!$B$54 -> 10000000 | C31: USD | D31: Es CAPEX: la instalación de dosificación se activa; los reactivos que consume después son OPEX.
A32: Subtotal Circuito de flotación | B32: =B29+B30+B31 -> 70000000 | C32: USD | D32: Alimenta el subtotal de CAPEX Planta.
A33: Filtros de concentrado | B33: =Assumptions!$B$55 -> 15000000 | C33: USD | D33: Es CAPEX: equipo fijo de vida útil plurianual.
A34: Almacenamiento y despacho de concentrado | B34: =Assumptions!$B$56 -> 10000000 | C34: USD | D34: Es CAPEX: instalación permanente.
A35: Dique de relaves (etapa inicial) | B35: =Assumptions!$B$57 -> 15000000 | C35: USD | D35: Es CAPEX: obra permanente que se sigue recreciendo con Sustaining CAPEX durante la vida de la mina.
A36: Subtotal Manejo de concentrado y relaves | B36: =B33+B34+B35 -> 40000000 | C36: USD | D36: Alimenta el subtotal de CAPEX Planta.
A37: Fundaciones y estructuras metálicas | B37: =Assumptions!$B$58 -> 15000000 | C37: USD | D37: Es CAPEX: obra civil permanente.
A38: Montaje electromecánico | B38: =Assumptions!$B$59 -> 10000000 | C38: USD | D38: Es CAPEX: costo directamente atribuible a poner los equipos de planta en condiciones de uso — se activa junto con ellos.
A39: Subtotal Obras civiles y montaje | B39: =B37+B38 -> 25000000 | C39: USD | D39: Alimenta el subtotal de CAPEX Planta.
A40: Subtotal CAPEX Planta | B40: =B24+B28+B32+B36+B39 -> 340000000 | C40: USD | D40: Alimenta la línea 'CAPEX Planta' de la hoja CAPEX.
A42: INFRAESTRUCTURA — COMPONENTES
A43: Longitud del camino de acceso | B43: =Assumptions!$B$60 -> 40 | C43: km | D43: Camino de acceso al proyecto desde la red vial existente.
...

Sheet Taxes
A1: Impuestos y regalías (aún no desarrollado)

Sheet Cash Flow
A1: CASH FLOW — Flujo de caja del proyecto (Etapa 5)
A2: Objetivo: proyectar el Flujo de Caja Libre del proyecto a lo largo de toda la vida de la mina (Año 0 = construcción, Años 1-15 = operación), como base para el VAN y la TIR de la Etapa 6.
A3: SIMPLIFICACIONES DE ESTA VERSIÓN: sin variación de ley año a año - sin Sustaining CAPEX - sin Capital de Trabajo (se deja en 0) - sin cierre de mina ni costos de cierre - sin inflación ni tipo de cambio - sin regalías (el Impuesto a las Ganancias usa una tasa única simplificada). Incorporado en Etapa 9: ramp-up de Toneladas Procesadas (fila editable) y separación de OPEX en fijo/variable (el fijo no escala con tonelaje, el variable sí).
A5: Concepto | B5: Año 0 | C5: Año 1 | D5: Año 2 | E5: Año 3 | F5: Año 4 | G5: Año 5 | H5: Año 6 | I5: Año 7 | J5: Año 8 | K5: Año 9 | L5: Año 10 | M5: Año 11 | N5: Año 12 | O5: Año 13 | P5: Año 14 | Q5: Año 15
A6: Capacidad de Planta en % | C6: 1 | D6: 1 | E6: 1 | F6: 1 | G6: 1 | H6: 1 | I6: 1 | J6: 1 | K6: 1 | L6: 1 | M6: 1 | N6: 1 | O6: 1 | P6: 1 | Q6: 1
A7: Toneladas procesadas | C7: =Toneladas_Procesadas*C6 -> 10000000 | D7: =Toneladas_Procesadas*D6 -> 10000000 | E7: =Toneladas_Procesadas*E6 -> 10000000 | F7: =Toneladas_Procesadas*F6 -> 10000000 | G7: =Toneladas_Procesadas*G6 -> 10000000 | H7: =Toneladas_Procesadas*H6 -> 10000000 | I7: =Toneladas_Procesadas*I6 -> 10000000 | J7: =Toneladas_Procesadas*J6 -> 10000000 | ... Q7: =Toneladas_Procesadas*Q6 -> 10000000
A8: Ley de cobre (head grade) | C8: =Ley_Cobre -> 0.0055 | D8: =Ley_Cobre -> 0.0055 | E8: =Ley_Cobre -> 0.0055 | F8: =Ley_Cobre -> 0.0055 | G8: =Ley_Cobre -> 0.0055 | H8: =Ley_Cobre -> 0.0055 | I8: =Ley_Cobre -> 0.0055 | J8: =Ley_Cobre -> 0.0055 | ... Q8: =Ley_Cobre -> 0.0055
A9: Metal contenido (t) | C9: =C7*C8 -> 55000 | D9: =D7*D8 -> 55000 | E9: =E7*E8 -> 55000 | F9: =F7*F8 -> 55000 | G9: =G7*G8 -> 55000 | H9: =H7*H8 -> 55000 | I9: =I7*I8 -> 55000 | J9: =J7*J8 -> 55000 | ... Q9: =Q7*Q8 -> 55000
A10: Recuperación metalúrgica | C10: =Recuperacion_Metalurgica -> 0.88 | D10: =Recuperacion_Metalurgica -> 0.88 | E10: =Recuperacion_Metalurgica -> 0.88 | F10: =Recuperacion_Metalurgica -> 0.88 | G10: =Recuperacion_Metalurgica -> 0.88 | H10: =Recuperacion_Metalurgica -> 0.88 | I10: =Recuperacion_Metalurgica -> 0.88 | J10: =Recuperacion_Metalurgica -> 0.88 | ... Q10: =Recuperacion_Metalurgica -> 0.88
A11: Metal recuperado (t) | C11: =C9*C10 -> 48400 | D11: =D9*D10 -> 48400 | E11: =E9*E10 -> 48400 | F11: =F9*F10 -> 48400 | G11: =G9*G10 -> 48400 | H11: =H9*H10 -> 48400 | I11: =I9*I10 -> 48400 | J11: =J9*J10 -> 48400 | ... Q11: =Q9*Q10 -> 48400
A12: Payability | C12: =Payability -> 0.965 | D12: =Payability -> 0.965 | E12: =Payability -> 0.965 | F12: =Payability -> 0.965 | G12: =Payability -> 0.965 | H12: =Payability -> 0.965 | I12: =Payability -> 0.965 | J12: =Payability -> 0.965 | ... Q12: =Payability -> 0.965
A13: Metal pagable (t) | C13: =C11*C12 -> 46706 | D13: =D11*D12 -> 46706 | E13: =E11*E12 -> 46706 | F13: =F11*F12 -> 46706 | G13: =G11*G12 -> 46706 | H13: =H11*H12 -> 46706 | I13: =I11*I12 -> 46706 | J13: =J11*J12 -> 46706 | ... Q13: =Q11*Q12 -> 46706
A14: Metal pagable (lb) | C14: =C13*Factor_Conversion_TnLb -> 1.0296898e+08 | D14: =D13*Factor_Conversion_TnLb -> 1.0296898e+08 | E14: =E13*Factor_Conversion_TnLb -> 1.0296898e+08 | F14: =F13*Factor_Conversion_TnLb -> 1.0296898e+08 | G14: =G13*Factor_Conversion_TnLb -> 1.0296898e+08 | H14: =H13*Factor_Conversion_TnLb -> 1.0296898e+08 | I14: =I13*Factor_Conversion_TnLb -> 1.0296898e+08 | J14: =J13*Factor_Conversion_TnLb -> 1.0296898e+08 | ... Q14: =Q13*Factor_Conversion_TnLb -> 1.0296898e+08
A15: Precio del cobre | C15: =Precio_Cobre -> 4.2 | D15: =Precio_Cobre -> 4.2 | E15: =Precio_Cobre -> 4.2 | F15: =Precio_Cobre -> 4.2 | G15: =Precio_Cobre -> 4.2 | H15: =Precio_Cobre -> 4.2 | I15: =Precio_Cobre -> 4.2 | J15: =Precio_Cobre -> 4.2 | ... Q15: =Precio_Cobre -> 4.2
A16: Ingreso Bruto Anual | C16: =C14*C15 -> 4.3246972e+08 | D16: =D14*D15 -> 4.3246972e+08 | E16: =E14*E15 -> 4.3246972e+08 | F16: =F14*F15 -> 4.3246972e+08 | G16: =G14*G15 -> 4.3246972e+08 | H16: =H14*H15 -> 4.3246972e+08 | I16: =I14*I15 -> 4.3246972e+08 | J16: =J14*J15 -> 4.3246972e+08 | ... Q16: =Q14*Q15 -> 4.3246972e+08
A17: Toneladas de concentrado | C17: =C11/Ley_Concentrado -> 161333.33 | D17: =D11/Ley_Concentrado -> 161333.33 | E17: =E11/Ley_Concentrado -> 161333.33 | F17: =F11/Ley_Concentrado -> 161333.33 | G17: =G11/Ley_Concentrado -> 161333.33 | H17: =H11/Ley_Concentrado -> 161333.33 | I17: =I11/Ley_Concentrado -> 161333.33 | J17: =J11/Ley_Concentrado -> 161333.33 | ... Q17: =Q11/Ley_Concentrado -> 161333.33
A18: Treatment Charge (TC) total | C18: =-C17*TC_Unitario -> -12906667 | D18: =-D17*TC_Unitario -> -12906667 | E18: =-E17*TC_Unitario -> -12906667 | F18: =-F17*TC_Unitario -> -12906667 | G18: =-G17*TC_Unitario -> -12906667 | H18: =-H17*TC_Unitario -> -12906667 | I18: =-I17*TC_Unitario -> -12906667 | J18: =-J17*TC_Unitario -> -12906667 | ... Q18: =-Q17*TC_Unitario -> -12906667
A19: Refining Charge (RC) total | C19: =-C14*RC_Unitario -> -8237518.5 | D19: =-D14*RC_Unitario -> -8237518.5 | E19: =-E14*RC_Unitario -> -8237518.5 | F19: =-F14*RC_Unitario -> -8237518.5 | G19: =-G14*RC_Unitario -> -8237518.5 | H19: =-H14*RC_Unitario -> -8237518.5 | I19: =-I14*RC_Unitario -> -8237518.5 | J19: =-J14*RC_Unitario -> -8237518.5 | ... Q19: =-Q14*RC_Unitario -> -8237518.5
A20: NSR (Ingresos netos) | C20: =C16+C18+C19 -> 4.1132554e+08 | D20: =D16+D18+D19 -> 4.1132554e+08 | E20: =E16+E18+E19 -> 4.1132554e+08 | F20: =F16+F18+F19 -> 4.1132554e+08 | G20: =G16+G18+G19 -> 4.1132554e+08 | H20: =H16+H18+H19 -> 4.1132554e+08 | I20: =I16+I18+I19 -> 4.1132554e+08 | J20: =J16+J18+J19 -> 4.1132554e+08 | ... Q20: =Q16+Q18+Q19 -> 4.1132554e+08
A21: Costo Mina (variable) | C21: =-C7*Costo_Mina_Unitario -> -32000000 | D21: =-D7*Costo_Mina_Unitario -> -32000000 | E21: =-E7*Costo_Mina_Unitario -> -32000000 | F21: =-F7*Costo_Mina_Unitario -> -32000000 | G21: =-G7*Costo_Mina_Unitario -> -32000000 | H21: =-H7*Costo_Mina_Unitario -> -32000000 | I21: =-I7*Costo_Mina_Unitario -> -32000000 | J21: =-J7*Costo_Mina_Unitario -> -32000000 | ... Q21: =-Q7*Costo_Mina_Unitario -> -32000000
A22: Costo Planta (variable) | C22: =-C7*Costo_Planta_Unitario -> -47000000 | D22: =-D7*Costo_Planta_Unitario -> -47000000 | E22: =-E7*Costo_Planta_Unitario -> -47000000 | F22: =-F7*Costo_Planta_Unitario -> -47000000 | G22: =-G7*Costo_Planta_Unitario -> -47000000 | H22: =-H7*Costo_Planta_Unitario -> -47000000 | I22: =-I7*Costo_Planta_Unitario -> -47000000 | J22: =-J7*Costo_Planta_Unitario -> -47000000 | ... Q22: =-Q7*Costo_Planta_Unitario -> -47000000
A23: Mano de obra de planta (fijo) | C23: =Mano_Obra_Fija -> -11000000 | D23: =Mano_Obra_Fija -> -11000000 | E23: =Mano_Obra_Fija -> -11000000 | F23: =Mano_Obra_Fija -> -11000000 | G23: =Mano_Obra_Fija -> -11000000 | H23: =Mano_Obra_Fija -> -11000000 | I23: =Mano_Obra_Fija -> -11000000 | J23: =Mano_Obra_Fija -> -11000000 | ... Q23: =Mano_Obra_Fija -> -11000000
A24: G&A (fijo) | C24: =GA_Fijo -> -45000000 | D24: =GA_Fijo -> -45000000 | E24: =GA_Fijo -> -45000000 | F24: =GA_Fijo -> -45000000 | G24: =GA_Fijo -> -45000000 | H24: =GA_Fijo -> -45000000 | I24: =GA_Fijo -> -45000000 | J24: =GA_Fijo -> -45000000 | ... Q24: =GA_Fijo -> -45000000
A25: OPEX Total Anual | C25: =C21+C22+C23+C24 -> -135000000 | D25: =D21+D22+D23+D24 -> -135000000 | E25: =E21+E22+E23+E24 -> -135000000 | F25: =F21+F22+F23+F24 -> -135000000 | G25: =G21+G22+G23+G24 -> -135000000 | H25: =H21+H22+H23+H24 -> -135000000 | I25: =I21+I22+I23+I24 -> -135000000 | J25: =J21+J22+J23+J24 -> -135000000 | ... Q25: =Q21+Q22+Q23+Q24 -> -135000000
A26: EBITDA | C26: =C20+C25 -> 2.7632554e+08 | D26: =D20+D25 -> 2.7632554e+08 | E26: =E20+E25 -> 2.7632554e+08 | F26: =F20+F25 -> 2.7632554e+08 | G26: =G20+G25 -> 2.7632554e+08 | H26: =H20+H25 -> 2.7632554e+08 | I26: =I20+I25 -> 2.7632554e+08 | J26: =J20+J25 -> 2.7632554e+08 | ... Q26: =Q20+Q25 -> 2.7632554e+08
A27: CAPEX | B27: =CAPEX_Inicial_Total -> -739200000 | C27: =0 -> 0 | D27: =0 -> 0 | E27: =0 -> 0 | F27: =0 -> 0 | G27: =0 -> 0 | H27: =0 -> 0 | I27: =0 -> 0 | J27: =0 -> 0 | ... Q27: =0 -> 0
A28: Depreciación (unidades de producción) | C28: =CAPEX_Inicial_Total*(C7/Reservas_Totales) -> -49280000 | D28: =CAPEX_Inicial_Total*(D7/Reservas_Totales) -> -49280000 | E28: =CAPEX_Inicial_Total*(E7/Reservas_Totales) -> -49280000 | F28: =CAPEX_Inicial_Total*(F7/Reservas_Totales) -> -49280000 | G28: =CAPEX_Inicial_Total*(G7/Reservas_Totales) -> -49280000 | H28: =CAPEX_Inicial_Total*(H7/Reservas_Totales) -> -49280000 | I28: =CAPEX_Inicial_Total*(I7/Reservas_Totales) -> -49280000 | J28: =CAPEX_Inicial_Total*(J7/Reservas_Totales) -> -49280000 | ... Q28: =CAPEX_Inicial_Total*(Q7/Reservas_Totales) -> -49280000
A29: EBIT | C29: =C26+C28 -> 2.2704554e+08 | D29: =D26+D28 -> 2.2704554e+08 | E29: =E26+E28 -> 2.2704554e+08 | F29: =F26+F28 -> 2.2704554e+08 | G29: =G26+G28 -> 2.2704554e+08 | H29: =H26+H28 -> 2.2704554e+08 | I29: =I26+I28 -> 2.2704554e+08 | J29: =J26+J28 -> 2.2704554e+08 | ... Q29: =Q26+Q28 -> 2.2704554e+08
A30: Impuestos | C30: =-Tasa_Impuesto*MAX(C29,0) -> -79465938 | D30: =-Tasa_Impuesto*MAX(D29,0) -> -79465938 | E30: =-Tasa_Impuesto*MAX(E29,0) -> -79465938 | F30: =-Tasa_Impuesto*MAX(F29,0) -> -79465938 | G30: =-Tasa_Impuesto*MAX(G29,0) -> -79465938 | H30: =-Tasa_Impuesto*MAX(H29,0) -> -79465938 | I30: =-Tasa_Impuesto*MAX(I29,0) -> -79465938 | J30: =-Tasa_Impuesto*MAX(J29,0) -> -79465938 | ... Q30: =-Tasa_Impuesto*MAX(Q29,0) -> -79465938
A31: Capital de Trabajo (variación) | C31: =0 -> 0 | D31: =0 -> 0 | E31: =0 -> 0 | F31: =0 -> 0 | G31: =0 -> 0 | H31: =0 -> 0 | I31: =0 -> 0 | J31: =0 -> 0 | ... Q31: =0 -> 0
A32: Provisión Cierre de Mina | B32: 0 | C32: 0 | D32: 0 | E32: 0 | F32: 0 | G32: 0 | H32: 0 | I32: 0 | J32: 0 | K32: 0 | L32: 0 | M32: 0 | N32: 0 | O32: 0 | P32: 0 | Q32: =CAPEX_Inicial_Total*Tasa_Provision_Cierre -> -73920000
A33: Flujo de Caja Libre (FCF) | B33: =B26+B27+B30+B31+B32 -> -739200000 | C33: =C26+C30+C31+C32 -> 1.968596e+08 | D33: =D26+D30+D31+D32 -> 1.968596e+08 | E33: =E26+E30+E31+E32 -> 1.968596e+08 | F33: =F26+F30+F31+F32 -> 1.968596e+08 | G33: =G26+G30+G31+G32 -> 1.968596e+08 | H33: =H26+H30+H31+H32 -> 1.968596e+08 | I33: =I26+I30+I31+I32 -> 1.968596e+08 | J33: =J26+J30+J31+J32 -> 1.968596e+08 | ... Q33: =Q26+Q30+Q31+Q32 -> 1.229396e+08
A34: Flujo de Caja Acumulado | B34: =B33 -> -739200000 | C34: =B34+C33 -> -5.423404e+08 | D34: =C34+D33 -> -3.454808e+08 | E34: =D34+E33 -> -1.486212e+08 | F34: =E34+F33 -> 48238399 | G34: =F34+G33 -> 2.45098e+08 | H34: =G34+H33 -> 4.419576e+08 | I34: =H34+I33 -> 6.388172e+08 | J34: =I34+J33 -> 8.356768e+08 | ... Q34: =P34+Q33 -> 2.139774e+09
A36: Filas de ayuda para el Precio de Equilibrio de Valuation (no tocar): FCF = a x Precio + b, año por año. Válido porque el FCF es una función lineal del Precio del cobre (mientras el EBIT sea positivo) — mismo principio que la Etapa 6, aplicado año por año en vez de a un único año representativo.
A37: a — Sensibilidad del FCF al Precio (USD/(USD/lb)) | B37: 0 | C37: =C14*(1-Tasa_Impuesto) -> 66929838 | D37: =D14*(1-Tasa_Impuesto) -> 66929838 | E37: =E14*(1-Tasa_Impuesto) -> 66929838 | F37: =F14*(1-Tasa_Impuesto) -> 66929838 | G37: =G14*(1-Tasa_Impuesto) -> 66929838 | H37: =H14*(1-Tasa_Impuesto) -> 66929838 | I37: =I14*(1-Tasa_Impuesto) -> 66929838 | J37: =J14*(1-Tasa_Impuesto) -> 66929838 | ... Q37: =Q14*(1-Tasa_Impuesto) -> 66929838
A38: b — FCF a Precio cero (USD) | B38: 0 | C38: =(1-Tasa_Impuesto)*(C18+C19+C25)-Tasa_Impuesto*C28+C32 -> -84245720 | D38: =(1-Tasa_Impuesto)*(D18+D19+D25)-Tasa_Impuesto*D28+D32 -> -84245720 | E38: =(1-Tasa_Impuesto)*(E18+E19+E25)-Tasa_Impuesto*E28+E32 -> -84245720 | F38: =(1-Tasa_Impuesto)*(F18+F19+F25)-Tasa_Impuesto*F28+F32 -> -84245720 | G38: =(1-Tasa_Impuesto)*(G18+G19+G25)-Tasa_Impuesto*G28+G32 -> -84245720 | H38: =(1-Tasa_Impuesto)*(H18+H19+H25)-Tasa_Impuesto*H28+H32 -> -84245720 | I38: =(1-Tasa_Impuesto)*(I18+I19+I25)-Tasa_Impuesto*I28+I32 -> -84245720 | J38: =(1-Tasa_Impuesto)*(J18+J19+J25)-Tasa_Impuesto*J28+J32 -> -84245720 | ... Q38: =(1-Tasa_Impuesto)*(Q18+Q19+Q25)-Tasa_Impuesto*Q28+Q32 -> -1.5816572e+08
A40: Control: Toneladas totales extraídas en la vida de mina vs Reservas | C40: =SUM(C7:Q7) -> 150000000 | D40: =Reservas_Totales -> 150000000 | E40: =C40-D40 -> 0
A41: Con el ramp-up, en los años 1-2 se procesa menos que a full capacidad, así que en 15 años fijos no se extrae el 100% de las Reservas_Totales (esta celda muestra cuánto queda sin extraer bajo este diseño). No estamos alargando la vida de mina más allá de 15 años — es una simplificación deliberada, no un error.

Sheet Valuation
A1: VALUATION — VAN, TIR, Payback y Precio de Equilibrio (Etapa 6)
A2: Objetivo: convertir el Flujo de Caja Libre de la Etapa 5 en los indicadores que la mesa de inversión usa para decidir: Valor Actual Neto (VAN), Tasa Interna de Retorno (TIR), Payback y Precio de Equilibrio del cobre.
A4: FLUJO DESCONTADO
A5: Concepto | B5: Año 0 | C5: Año 1 | D5: Año 2 | E5: Año 3 | F5: Año 4 | G5: Año 5 | H5: Año 6 | I5: Año 7 | J5: Año 8 | K5: Año 9 | L5: Año 10 | M5: Año 11 | N5: Año 12 | O5: Año 13 | P5: Año 14 | Q5: Año 15 | R5: Comentario / lógica
A6: Flujo de Caja Libre (FCF) | B6: ='Cash Flow'!B33 -> -739200000 | C6: ='Cash Flow'!C33 -> 1.968596e+08 | D6: ='Cash Flow'!D33 -> 1.968596e+08 | E6: ='Cash Flow'!E33 -> 1.968596e+08 | F6: ='Cash Flow'!F33 -> 1.968596e+08 | G6: ='Cash Flow'!G33 -> 1.968596e+08 | H6: ='Cash Flow'!H33 -> 1.968596e+08 | I6: ='Cash Flow'!I33 -> 1.968596e+08 | ... Q6: ='Cash Flow'!Q33 -> 1.229396e+08 | R6: Referencia directa a Cash Flow!FCF (fila 16). Año 0 = CAPEX inicial (negativo).
A7: VAN Acumulado | B7: ='Cash Flow'!$B$33 -> -739200000 | C7: ='Cash Flow'!$B$33+NPV(WACC,'Cash Flow'!$C$33:C33) -> -5.6023673e+08 | D7: ='Cash Flow'!$B$33+NPV(WACC,'Cash Flow'!$C$33:D33) -> -3.9754284e+08 | E7: ='Cash Flow'!$B$33+NPV(WACC,'Cash Flow'!$C$33:E33) -> -2.4963931e+08 | F7: ='Cash Flow'!$B$33+NPV(WACC,'Cash Flow'!$C$33:F33) -> -1.1518156e+08 | G7: ='Cash Flow'!$B$33+NPV(WACC,'Cash Flow'!$C$33:G33) -> 7052766 | H7: ='Cash Flow'!$B$33+NPV(WACC,'Cash Flow'!$C$33:H33) -> 1.1817488e+08 | I7: ='Cash Flow'!$B$33+NPV(WACC,'Cash Flow'!$C$33:I33) -> 2.1919498e+08 | J7: ='Cash Flow'!$B$33+NPV(WACC,'Cash Flow'!$C$33:J33) -> 3.1103144e+08 | ... Q7: ='Cash Flow'!$B$33+NPV(WACC,'Cash Flow'!$C$33:Q33) -> 7.4043391e+08 | R7: VAN calculado con la función NPV/VNA de Excel hasta ese año: 'Cash Flow'!$B$16 + NPV(Tasa de Descuento, rango de FCF desde el Año 1 hasta ese año). Excel descuenta internamente cada flujo — no hace falta armar un factor a mano. El valor del Año 0 es simplemente el CAPEX, porque todavía no hay flujos futuros que descontar. El VAN del proyecto es el último valor de esta fila (Año 15).
A9: RESULTADOS DE VALUACIÓN
A10: Concepto | B10: Valor | C10: Unidad | D10: Comentario / lógica
A11: Vida de Mina (LOM) | B11: =Reservas_Totales/Toneladas_Procesadas -> 15 | C11: años | D11: Reservas totales / Toneladas procesadas por año. Confirma los 15 años usados en Cash Flow.
A12: Tasa de Descuento (WACC) | B12: =WACC -> 0.1 | C12: % | D12: Referencia directa al supuesto de Assumptions.
A13: VAN (Valor Actual Neto) | B13: =+B6+NPV(B12,C6:Q6) -> 7.4043391e+08 | C13: USD | D13: Trae el último valor (Año 15) de la fila VAN Acumulado de arriba, calculada con la función NPV/VNA de Excel. Si es positivo, el proyecto crea valor por encima del retorno mínimo exigido (la Tasa de Descuento).
A14: TIR (Tasa Interna de Retorno) | B14: =IRR(B6:Q6) -> 0.25684908 | C14: % | D14: Tasa de descuento que hace VAN = 0. Se compara contra la Tasa de Descuento: si TIR > WACC, el proyecto conviene.
A15: Payback Simple (sin descuento) | B15: =IFERROR((COUNTIF('Cash Flow'!$B$34:$Q$34,"<0")-1)+(-INDEX('Cash Flow'!$B$34:$Q$34,COUNTIF('Cash Flow'!$B$34:$Q$34,"<0"))/INDEX('Cash Flow'!$B$33:$Q$33,COUNTIF('Cash Flow'!$B$34:$Q$34,"<0")+1)),"N/A") -> 3.7549604 | C15: años | D15: Año en que el FCF Acumulado de Cash Flow cruza cero
A16: Payback Descontado | B16: =IFERROR((COUNTIF($B$7:$Q$7,"<0")-1)+(-INDEX($B$7:$Q$7,COUNTIF($B$7:$Q$7,"<0"))/(INDEX($B$7:$Q$7,COUNTIF($B$7:$Q$7,"<0")+1)-INDEX($B$7:$Q$7,COUNTIF($B$7:$Q$7,"<0")))),"N/A") -> 4.9423013 | C16: años | D16: Igual que el Payback Simple, pero usando el VAN Acumulado (fila de arriba) en vez del FCF sin descontar. El denominador es la diferencia entre dos VAN Acumulados consecutivos — el valor presente que aporta ese año puntual. Siempre es mayor o igual al Payback Simple, porque descontar castiga los flujos futuros.
A18: PRECIO DE EQUILIBRIO (BREAK-EVEN)
A19: Lógica (Etapa 9): el FCF de cada año es una función lineal del Precio del cobre (mientras el EBIT de ese año sea positivo): FCF_año = a_año x Precio + b_año. Esto sigue siendo válido año a año aunque el tonelaje varíe por el ramp-up — lo que cambia es que ahora hay que sumar el VAN de esa parte 'a' y esa parte 'b' con NPV() a través de los 15 años
A21: Concepto | B21: Valor | C21: Unidad | D21: Comentario / lógica
A22: NPV de 'a' (sensibilidad del FCF al Precio, descontada) | B22: =NPV(WACC,'Cash Flow'!C37:Q37) -> 5.0907367e+08 | C22: USD/(USD/lb) | D22: Este es la pendiente del VAN COMPLETO del proyecto: por cada dólar que sube el precio del cobre, el VAN de todo el proyecto (ya traído a valor de hoy) sube USD 476,4 millones.
A23: NPV de 'b' (FCF a Precio cero, descontado) | B23: =NPV(WACC,'Cash Flow'!C38:Q38) -> -6.5847551e+08 | C23: USD | D23: Es la ordenada al origen de esa misma recta: lo que valdría el proyecto (sin contar el CAPEX inicial) si el cobre no aportara nada de valor marginal por precio.
A24: CAPEX Inicial (Año 0) | B24: =CAPEX_Inicial_Total -> -739200000 | C24: USD
A25: Precio de Equilibrio (Break-even) | B25: =-(B24+B23)/B22 -> 2.745527 | C25: USD/lb | D25: Se puede obtener tambien haciendo buscar objetivo donde VAN = 0
A26: Precio actual del cobre (referencia) | B26: =Precio_Cobre -> 4.2 | C26: USD/lb
A27: Margen de seguridad sobre el precio | B27: =(B26-B25)/B26 -> 0.34630309 | C27: % | D27: ¿Hasta qué precio de cobre puede caer antes de que el VAN llegue a cero? El precio del cobre podría caer hasta un 32,2% desde donde está hoy, y el proyecto todavía estaría rindiendo exactamente tu mínimo exigido (VAN=0, TIR=WACC)
A28: Verificación: VAN al Precio de Equilibrio (debe dar ≈0) | B28: =B24+B22*B25+B23 -> 0 | C28: USD

Sheet Sensitivities
B1: SENSITIVITIES — Análisis de sensibilidad de una variable a la vez (Etapa 7)
B2: Objetivo: medir cuánto se mueve el VAN (y la TIR) del caso base cuando UNA sola variable clave cambia, dejando todas las demás fijas ('one-at-a-time')
B3: Todas las celdas de esta hoja recalculan la cadena completa año por año (15 años, con el mismo ramp-up y la separación OPEX fijo/variable de Cash Flow) y usan NPV()/IRR() reales -- ya no el atajo del Factor de Anualidad / RATE(). Etapa 9.
B4: Truco usado para no repetir las ~20 filas intermedias 5 veces por variable: como acá se mueve UNA sola variable a la vez (todo lo demás queda en su valor base), el FCF de cada año es una función lineal de esa variable: FCF_año = a_año x Valor + b_año. Estos 'a' y 'b' se calculan UNA vez por año (dos filas por bloque, con Año 0..Año 15 en columnas, igual que Cash Flow) y de ahí se arma el FCF real de cada uno de los 5 escenarios de shock -- el NPV()/IRR() final (columnas VAN/TIR) es sobre ese flujo real, no una aproximación. Etapa 9b: se reorientó la hoja para que los años queden en columnas (como en Cash Flow/Scenarios) en vez de en filas.
B6: RANGO DE VARIACIÓN APLICADO
B7: % de cambio sobre el valor base | F7: % | G7: -0.2 | H7: -0.1 | I7: 0 | J7: 0.1 | K7: 0.2
B8: Todos los bloques de abajo usan esta misma fila como referencia. Cambiar estos 5 valores actualiza el rango de todas las variables a la vez.
B10: RESUMEN — IMPACTO EN EL VAN POR VARIABLE (ordenado por magnitud)
B11: Variable | C11: Unidad | D11: VAN a -20% | E11: VAN Base (0%) | F11: VAN a 20% | G11: Rango |ΔVAN| | H11: Ranking
B12: Precio del cobre | C12: USD/lb | D12: =C46 -> 3.1281202e+08 | E12: =C48 -> 7.4043391e+08 | F12: =C50 -> 1.1680558e+09 | G12: =ABS(F12-D12) -> 8.5524377e+08 | H12: =RANK(G12,$G$12:$G$16,0) -> 1 | I12: Si baja afecta negativamente al proyecto
B13: Ley de cobre | C13: % Cu | D13: =C58 -> 3.5141505e+08 | E13: =C60 -> 7.5812977e+08 | F13: =C62 -> 1.1648445e+09 | G13: =ABS(F13-D13) -> 8.1342943e+08 | H13: =RANK(G13,$G$12:$G$16,0) -> 3 | I13: Si baja afecta negativamente al proyecto
B14: Recuperación metalúrgica | C14: % | D14: =C70 -> 3.5141505e+08 | E14: =C72 -> 7.5812977e+08 | F14: =C74 -> 1.1648445e+09 | G14: =ABS(F14-D14) -> 8.1342943e+08 | H14: =RANK(G14,$G$12:$G$16,0) -> 2 | I14: Si baja afecta negativamente al proyecto
B15: CAPEX Inicial Total | C15: USD | D15: =C82 -> 8.7973184e+08 | E15: =C84 -> 7.5812977e+08 | F15: =C86 -> 6.365277e+08 | G15: =ABS(F15-D15) -> 2.4320414e+08 | H15: =RANK(G15,$G$12:$G$16,0) -> 5 | I15: Si baja afecta positivamente al proyecto
B16: OPEX Total Anual | C16: USD | D16: =C94 -> 8.739206e+08 | E16: =C96 -> 7.4043391e+08 | F16: =C98 -> 6.0694721e+08 | G16: =ABS(F16-D16) -> 2.6697339e+08 | H16: =RANK(G16,$G$12:$G$16,0) -> 4 | I16: Si baja afecta positivamente al proyecto
B17: (columnas auxiliares para el gráfico, no editar)
L19: ¿cuál es el rango total de resultados posibles si esta variable se mueve hasta el límite que definimos como razonable?
L25: Base (mín) | M25: Rango
L26: =MIN(D12,F12) -> 3.1281202e+08 | M26: =G12 -> 8.5524377e+08
L27: =MIN(D13,F13) -> 3.5141505e+08 | M27: =G13 -> 8.1342943e+08
L28: =MIN(D14,F14) -> 3.5141505e+08 | M28: =G14 -> 8.1342943e+08
L29: =MIN(D15,F15) -> 6.365277e+08 | M29: =G15 -> 2.4320414e+08
L30: =MIN(D16,F16) -> 6.0694721e+08 | M30: =G16 -> 2.6697339e+08
B38: DETALLE POR VARIABLE (una variable a la vez, todas las demás en su valor base) -- años en columnas, igual que Cash Flow
B40: 1. PRECIO DEL COBRE — sensibilidad del VAN y la TIR, año por año
B41: Se mueve el Precio del cobre (Assumptions) y se recalcula la cadena completa, año por año.
B42: Concepto | C42: VAN | D42: TIR | E42: Valor de la variable | F42: Año 0 | G42: Año 1 | H42: Año 2 | I42: Año 3 | J42: Año 4 | K42: Año 5 | L42: Año 6 | M42: Año 7 | N42: Año 8 | O42: Año 9 | P42: Año 10 | Q42: Año 11 | R42: Año 12 | S42: Año 13 | T42: Año 14 | U42: Año 15
B43: a — Sensibilidad del FCF a la variable (no editar) | F43: 0 | G43: ='Cash Flow'!C37 -> 66929838 | H43: ='Cash Flow'!D37 -> 66929838 | I43: ='Cash Flow'!E37 -> 66929838 | J43: ='Cash Flow'!F37 -> 66929838 | K43: ='Cash Flow'!G37 -> 66929838 | L43: ='Cash Flow'!H37 -> 66929838 | M43: ='Cash Flow'!I37 -> 66929838 | N43: ='Cash Flow'!J37 -> 66929838 | ... U43: ='Cash Flow'!Q37 -> 66929838
B44: b — FCF con la variable en su valor base 'cero' (no editar) | F44: 0 | G44: ='Cash Flow'!C38 -> -84245720 | H44: ='Cash Flow'!D38 -> -84245720 | I44: ='Cash Flow'!E38 -> -84245720 | J44: ='Cash Flow'!F38 -> -84245720 | K44: ='Cash Flow'!G38 -> -84245720 | L44: ='Cash Flow'!H38 -> -84245720 | M44: ='Cash Flow'!I38 -> -84245720 | N44: ='Cash Flow'!J38 -> -84245720 | ... U44: ='Cash Flow'!Q38 -> -1.5816572e+08
B45: Cada fila de abajo es un escenario de shock completo (Año 0 a Año 15, más VAN, TIR y el valor de la variable en ese shock) -- FCF = a x Valor (o x % shock en OPEX) + b.
B46: ="FCF y VAN — PRECIO DEL COBRE (" & TEXT(G$7,"0%") & ")" -> FCF y VAN — PRECIO DEL COBRE (-20%) | C46: =F46+NPV(WACC,G46:U46) -> 3.1281202e+08 | D46: =IFERROR(IRR(F46:U46),"N/A") -> 0.17077966 | E46: =Precio_Cobre*(1+G$7) -> 3.36 | F46: =CAPEX_Inicial_Total -> -739200000 | G46: =G43*$E46+G44 -> 1.4063854e+08 | H46: =H43*$E46+H44 -> 1.4063854e+08 | I46: =I43*$E46+I44 -> 1.4063854e+08 | J46: =J43*$E46+J44 -> 1.4063854e+08 | K46: =K43*$E46+K44 -> 1.4063854e+08 | L46: =L43*$E46+L44 -> 1.4063854e+08 | M46: =M43*$E46+M44 -> 1.4063854e+08 | N46: =N43*$E46+N44 -> 1.4063854e+08 | ... U46: =U43*$E46+U44 -> 66718536
B47: ="FCF y VAN — PRECIO DEL COBRE (" & TEXT(H$7,"0%") & ")" -> FCF y VAN — PRECIO DEL COBRE (-10%) | C47: =F47+NPV(WACC,G47:U47) -> 5.2662297e+08 | D47: =IFERROR(IRR(F47:U47),"N/A") -> 0.21479718 | E47: =Precio_Cobre*(1+H$7) -> 3.78 | F47: =CAPEX_Inicial_Total -> -739200000 | G47: =G43*$E47+G44 -> 1.6874907e+08 | H47: =H43*$E47+H44 -> 1.6874907e+08 | I47: =I43*$E47+I44 -> 1.6874907e+08 | J47: =J43*$E47+J44 -> 1.6874907e+08 | K47: =K43*$E47+K44 -> 1.6874907e+08 | L47: =L43*$E47+L44 -> 1.6874907e+08 | M47: =M43*$E47+M44 -> 1.6874907e+08 | N47: =N43*$E47+N44 -> 1.6874907e+08 | ... U47: =U43*$E47+U44 -> 94829068
B48: ="FCF y VAN — PRECIO DEL COBRE (" & TEXT(I$7,"0%") & ")" -> FCF y VAN — PRECIO DEL COBRE (0%) | C48: =F48+NPV(WACC,G48:U48) -> 7.4043391e+08 | D48: =IFERROR(IRR(F48:U48),"N/A") -> 0.25684908 | E48: =Precio_Cobre*(1+I$7) -> 4.2 | F48: =CAPEX_Inicial_Total -> -739200000 | G48: =G43*$E48+G44 -> 1.968596e+08 | H48: =H43*$E48+H44 -> 1.968596e+08 | I48: =I43*$E48+I44 -> 1.968596e+08 | J48: =J43*$E48+J44 -> 1.968596e+08 | K48: =K43*$E48+K44 -> 1.968596e+08 | L48: =L43*$E48+L44 -> 1.968596e+08 | M48: =M43*$E48+M44 -> 1.968596e+08 | N48: =N43*$E48+N44 -> 1.968596e+08 | ... U48: =U43*$E48+U44 -> 1.229396e+08
B49: ="FCF y VAN — PRECIO DEL COBRE (" & TEXT(J$7,"0%") & ")" -> FCF y VAN — PRECIO DEL COBRE (10%) | C49: =F49+NPV(WACC,G49:U49) -> 9.5424485e+08 | D49: =IFERROR(IRR(F49:U49),"N/A") -> 0.29763463 | E49: =Precio_Cobre*(1+J$7) -> 4.62 | F49: =CAPEX_Inicial_Total -> -739200000 | G49: =G43*$E49+G44 -> 2.2497013e+08 | H49: =H43*$E49+H44 -> 2.2497013e+08 | I49: =I43*$E49+I44 -> 2.2497013e+08 | J49: =J43*$E49+J44 -> 2.2497013e+08 | K49: =K43*$E49+K44 -> 2.2497013e+08 | L49: =L43*$E49+L44 -> 2.2497013e+08 | M49: =M43*$E49+M44 -> 2.2497013e+08 | N49: =N43*$E49+N44 -> 2.2497013e+08 | ... U49: =U43*$E49+U44 -> 1.5105013e+08
B50: ="FCF y VAN — PRECIO DEL COBRE (" & TEXT(K$7,"0%") & ")" -> FCF y VAN — PRECIO DEL COBRE (20%) | C50: =F50+NPV(WACC,G50:U50) -> 1.1680558e+09 | D50: =IFERROR(IRR(F50:U50),"N/A") -> 0.3375787 | E50: =Precio_Cobre*(1+K$7) -> 5.04 | F50: =CAPEX_Inicial_Total -> -739200000 | G50: =G43*$E50+G44 -> 2.5308066e+08 | H50: =H43*$E50+H44 -> 2.5308066e+08 | I50: =I43*$E50+I44 -> 2.5308066e+08 | J50: =J43*$E50+J44 -> 2.5308066e+08 | K50: =K43*$E50+K44 -> 2.5308066e+08 | L50: =L43*$E50+L44 -> 2.5308066e+08 | M50: =M43*$E50+M44 -> 2.5308066e+08 | N50: =N43*$E50+N44 -> 2.5308066e+08 | ... U50: =U43*$E50+U44 -> 1.7916066e+08
B52: 2. LEY DE COBRE (HEAD GRADE) — sensibilidad del VAN y la TIR, año por año
B53: Se mueve la Ley promedio del yacimiento. Afecta el metal contenido y todo lo que se mide en metal, pero no el OPEX ni el CAPEX (dependen de toneladas, no de ley).
B54: Concepto | C54: VAN | D54: TIR | E54: Valor de la variable | F54: Año 0 | G54: Año 1 | H54: Año 2 | I54: Año 3 | J54: Año 4 | K54: Año 5 | L54: Año 6 | M54: Año 7 | N54: Año 8 | O54: Año 9 | P54: Año 10 | Q54: Año 11 | R54: Año 12 | S54: Año 13 | T54: Año 14 | U54: Año 15
B55: a — Sensibilidad del FCF a la variable (no editar) | F55: 0 | G55: =(1-Tasa_Impuesto)*'Cash Flow'!C20/Ley_Cobre -> 4.86112e+10 | H55: =(1-Tasa_Impuesto)*'Cash Flow'!D20/Ley_Cobre -> 4.86112e+10 | I55: =(1-Tasa_Impuesto)*'Cash Flow'!E20/Ley_Cobre -> 4.86112e+10 | J55: =(1-Tasa_Impuesto)*'Cash Flow'!F20/Ley_Cobre -> 4.86112e+10 | K55: =(1-Tasa_Impuesto)*'Cash Flow'!G20/Ley_Cobre -> 4.86112e+10 | L55: =(1-Tasa_Impuesto)*'Cash Flow'!H20/Ley_Cobre -> 4.86112e+10 | M55: =(1-Tasa_Impuesto)*'Cash Flow'!I20/Ley_Cobre -> 4.86112e+10 | N55: =(1-Tasa_Impuesto)*'Cash Flow'!J20/Ley_Cobre -> 4.86112e+10 | ... U55: =(1-Tasa_Impuesto)*'Cash Flow'!Q20/Ley_Cobre -> 4.86112e+10
B56: b — FCF con la variable en su valor base 'cero' (no editar) | F56: 0 | G56: =(1-Tasa_Impuesto)*'Cash Flow'!C25-Tasa_Impuesto*'Cash Flow'!C28 -> -70502000 | H56: =(1-Tasa_Impuesto)*'Cash Flow'!D25-Tasa_Impuesto*'Cash Flow'!D28 -> -70502000 | I56: =(1-Tasa_Impuesto)*'Cash Flow'!E25-Tasa_Impuesto*'Cash Flow'!E28 -> -70502000 | J56: =(1-Tasa_Impuesto)*'Cash Flow'!F25-Tasa_Impuesto*'Cash Flow'!F28 -> -70502000 | K56: =(1-Tasa_Impuesto)*'Cash Flow'!G25-Tasa_Impuesto*'Cash Flow'!G28 -> -70502000 | L56: =(1-Tasa_Impuesto)*'Cash Flow'!H25-Tasa_Impuesto*'Cash Flow'!H28 -> -70502000 | M56: =(1-Tasa_Impuesto)*'Cash Flow'!I25-Tasa_Impuesto*'Cash Flow'!I28 -> -70502000 | N56: =(1-Tasa_Impuesto)*'Cash Flow'!J25-Tasa_Impuesto*'Cash Flow'!J28 -> -70502000 | ... U56: =(1-Tasa_Impuesto)*'Cash Flow'!Q25-Tasa_Impuesto*'Cash Flow'!Q28 -> -70502000
B57: Cada fila de abajo es un escenario de shock completo (Año 0 a Año 15, más VAN, TIR y el valor de la variable en ese shock) -- FCF = a x Valor (o x % shock en OPEX) + b.
...

Sheet Scenarios
A1: SCENARIOS — Simulación de escenarios combinados (Etapa 9)
A2: Objetivo: mover VARIAS variables al mismo tiempo (no una a la vez, como en Sensitivities) y ver cómo se mueve el VAN, la TIR y el resto de la cadena, año por año y con ramp-up real
A4: SUPUESTOS POR ESCENARIO (% de cambio sobre el valor base) — EDITABLE
A5: Concepto | B5: Unidad | C5: Base | D5: Optimista | E5: Pesimista | F5: Personalizado | G5: Comentario / lógica
A6: Precio del cobre | B6: % | C6: 0 | D6: 0.2 | E6: 0 | F6: 0 | G6: % de cambio sobre Precio_Cobre. Un % positivo es una mejora.
A7: Ley de cobre (head grade) | B7: % | C7: 0 | D7: 0.05 | E7: -0.15 | F7: 0 | G7: % de cambio sobre Ley_Cobre. Un % positivo es una mejora (más metal por tonelada).
A8: Recuperación metalúrgica | B8: % | C8: 0 | D8: 0.03 | E8: -0.09 | F8: 0 | G8: % de cambio sobre Recuperacion_Metalurgica. Un % positivo es una mejora.
A9: CAPEX Inicial Total | B9: % | C9: 0 | D9: -0.05 | E9: 0.1 | F9: 0 | G9: % de cambio sobre CAPEX_Inicial_Total. Acá un % positivo es un incremento de costo operativo.
A10: OPEX Total Anual | B10: % | C10: 0 | D10: -0.05 | E10: 0.1 | F10: 0 | G10: % de cambio sobre OPEX_Total_Anual. Acá un % positivo es un incremento de costo operativo.
A11: Toneladas Procesadas (ritmo de planta) | B11: % | C11: 0 | D11: 0.13 | E11: -0.25 | F11: 0 | G11: % de cambio sobre Toneladas_Procesadas.
A13: VALORES RESULTANTES DEL ESCENARIO
A14: Concepto | B14: Unidad | C14: Base | D14: Optimista | E14: Pesimista | F14: Personalizado | G14: Comentario / lógica
A15: Toneladas Procesadas | B15: t/año | C15: =Toneladas_Procesadas*(1+C$11) -> 10000000 | D15: =Toneladas_Procesadas*(1+D$11) -> 11300000 | E15: =Toneladas_Procesadas*(1+E$11) -> 7500000 | F15: =Toneladas_Procesadas*(1+F$11) -> 10000000
A16: Precio del cobre | B16: USD/lb | C16: =Precio_Cobre*(1+C$6) -> 4.2 | D16: =Precio_Cobre*(1+D$6) -> 5.04 | E16: =Precio_Cobre*(1+E$6) -> 4.2 | F16: =Precio_Cobre*(1+F$6) -> 4.2
A17: Ley de cobre | B17: % Cu | C17: =Ley_Cobre*(1+C$7) -> 0.0055 | D17: =Ley_Cobre*(1+D$7) -> 0.005775 | E17: =Ley_Cobre*(1+E$7) -> 0.004675 | F17: =Ley_Cobre*(1+F$7) -> 0.0055
A18: Recuperación metalúrgica | B18: % | C18: =Recuperacion_Metalurgica*(1+C$8) -> 0.88 | D18: =Recuperacion_Metalurgica*(1+D$8) -> 0.9064 | E18: =Recuperacion_Metalurgica*(1+E$8) -> 0.8008 | F18: =Recuperacion_Metalurgica*(1+F$8) -> 0.88
A19: CAPEX Inicial Total | B19: Miles USD | C19: =CAPEX_Inicial_Total*(1+C$9) -> -739200000 | D19: =CAPEX_Inicial_Total*(1+D$9) -> -702240000 | E19: =CAPEX_Inicial_Total*(1+E$9) -> -8.1312e+08 | F19: =CAPEX_Inicial_Total*(1+F$9) -> -739200000
A20: OPEX Total | B20: Miles USD | C20: =SUM(C55:Q55) -> -2025000000 | D20: =SUM(C93:Q93) -> -2023453925 | E20: =SUM(C131:Q131) -> -1.8657788e+09 | F20: =SUM(C169:Q169) -> -1981550000
A21: Provisión Cierre de Mina Total | B21: Miles USD | C21: =Q62 -> -73920000 | D21: =Q100 -> -70224000 | E21: =Q138 -> -81312000 | F21: =Q176 -> -73920000
A23: RESUMEN COMPARATIVO — VAN, TIR y otros indicadores clave por escenario
A24: Concepto | B24: Unidad | C24: Base | D24: Optimista | E24: Pesimista | F24: Personalizado | G24: Comentario / lógica
A25: VAN (Valor Actual Neto) | B25: USD | C25: =B65 -> 7.4043391e+08 | D25: =B103 -> 1.5723265e+09 | E25: =B141 -> -2.3330708e+08 | F25: =B179 -> 6.2669575e+08
A26: TIR (Tasa Interna de Retorno) | B26: % | C26: =B66 -> 0.25684908 | D26: =B104 -> 0.38570996 | E26: =B142 -> 0.04718561 | F26: =B180 -> 0.22209348
A27: Precio de Equilibrio (Break-even) | B27: USD/lb | C27: =-(C19+NPV(WACC,C68:Q68))/NPV(WACC,C67:Q67) -> 2.745527 | D27: =-(D19+NPV(WACC,D106:Q106))/NPV(WACC,D105:Q105) -> 2.3023357 | E27: =-(E19+NPV(WACC,E144:Q144))/NPV(WACC,E143:Q143) -> 4.9947069 | F27: =-(F19+NPV(WACC,F182:Q182))/NPV(WACC,F181:Q181) -> 2.9312772 | G27: Precio del cobre al cual el VAN del escenario es 0, con el mismo método lineal (FCF = a x Precio + b) de Valuation Seccion 5, usando el CAPEX y la cadena propia de cada escenario.
A28: Payback Simple (sin descuento) | B28: años | C28: =IFERROR((COUNTIF($B$64:$Q$64,"<0")-1)+(-INDEX($B$64:$Q$64,COUNTIF($B$64:$Q$64,"<0"))/INDEX($B$63:$Q$63,COUNTIF($B$64:$Q$64,"<0")+1)),"N/A") -> 3.7549604 | D28: =IFERROR((COUNTIF($B$102:$Q$102,"<0")-1)+(-INDEX($B$102:$Q$102,COUNTIF($B$102:$Q$102,"<0"))/INDEX($B$101:$Q$101,COUNTIF($B$102:$Q$102,"<0")+1)),"N/A") -> 2.7743213 | E28: =IFERROR((COUNTIF($B$140:$Q$140,"<0")-1)+(-INDEX($B$140:$Q$140,COUNTIF($B$140:$Q$140,"<0"))/INDEX($B$139:$Q$139,COUNTIF($B$140:$Q$140,"<0")+1)),"N/A") -> 10.157174 | F28: =IFERROR((COUNTIF($B$178:$Q$178,"<0")-1)+(-INDEX($B$178:$Q$178,COUNTIF($B$178:$Q$178,"<0"))/INDEX($B$177:$Q$177,COUNTIF($B$178:$Q$178,"<0")+1)),"N/A") -> 4.4066572 | G28: Años para recuperar el CAPEX inicial con el FCF simple (sin descuento) de cada escenario — mismo metodo que Valuation!B15.
